Workbook

Sheet NeatRescue — Hackathon submissi
A1: NeatRescue — Hackathon submission · User-reported facts — not independently audited
A2: Financial model (5 pages) · Main Scenario
A4: Variable / dimension | B4: Value
A5: Actual customers | B5: =0 -> 0
A6: Actual monthly revenue | B6: =0 -> 0
A7: Actual cash | B7: =0 -> 0
A8: Committed funding | B8: =0 -> 0
A9: Synthetic incorrect payment rows | B9: =4 -> 4
A10: Synthetic rows after incomplete fix | B10: =1 -> 1
A11: Synthetic correct rows after independent verification | B11: =3 -> 3

Sheet NeatRescue — Hackathon subm (2)
A1: NeatRescue — Hackathon submission · 12-month scenario comparison — hypothetical
A2: Financial model (5 pages) · Main Scenario
A4: Variable / dimension | B4: Value | C4: Value > Conservative | D4: Value > Growth | E4: Value > Bootstrap $5,000 — hypothetical | F4: Value > Bootstrap no-sales stress — hypothetical
A5: 12-month revenue | B5: =SUM('NeatRescue — Hackathon subm (3)'!B5,'NeatRescue — Hackathon subm (3)'!C5,'NeatRescue — Hackathon subm (3)'!D5,'NeatRescue — Hackathon subm (3)'!E5,'NeatRescue — Hackathon subm (3)'!F5,'NeatRescue — Hackathon subm (3)'!G5,'NeatRescue — Hackathon subm (3)'!H5,'NeatRescue — Hackathon subm (3)'!I5,'NeatRescue — Hackathon subm (3)'!J5,'NeatRescue — Hackathon subm (3)'!K5,'NeatRescue — Hackathon subm (3)'!L5,'NeatRescue — Hackathon subm (3)'!M5) -> 31649.645 | C5: =SUM('NeatRescue — Hackathon subm (3)'!B6,'NeatRescue — Hackathon subm (3)'!C6,'NeatRescue — Hackathon subm (3)'!D6,'NeatRescue — Hackathon subm (3)'!E6,'NeatRescue — Hackathon subm (3)'!F6,'NeatRescue — Hackathon subm (3)'!G6,'NeatRescue — Hackathon subm (3)'!H6,'NeatRescue — Hackathon subm (3)'!I6,'NeatRescue — Hackathon subm (3)'!J6,'NeatRescue — Hackathon subm (3)'!K6,'NeatRescue — Hackathon subm (3)'!L6,'NeatRescue — Hackathon subm (3)'!M6) -> 7062.133 | D5: =SUM('NeatRescue — Hackathon subm (3)'!B7,'NeatRescue — Hackathon subm (3)'!C7,'NeatRescue — Hackathon subm (3)'!D7,'NeatRescue — Hackathon subm (3)'!E7,'NeatRescue — Hackathon subm (3)'!F7,'NeatRescue — Hackathon subm (3)'!G7,'NeatRescue — Hackathon subm (3)'!H7,'NeatRescue — Hackathon subm (3)'!I7,'NeatRescue — Hackathon subm (3)'!J7,'NeatRescue — Hackathon subm (3)'!K7,'NeatRescue — Hackathon subm (3)'!L7,'NeatRescue — Hackathon subm (3)'!M7) -> 83648.393 | E5: =SUM('Model inputs'!D67,'Model inputs'!E67,'Model inputs'!F67,'Model inputs'!G67,'Model inputs'!H67,'Model inputs'!I67,'Model inputs'!J67,'Model inputs'!K67,'Model inputs'!L67,'Model inputs'!M67,'Model inputs'!N67,'Model inputs'!B67) -> 31649.645 | F5: =SUM('Model inputs'!D62,'Model inputs'!E62,'Model inputs'!F62,'Model inputs'!G62,'Model inputs'!H62,'Model inputs'!I62,'Model inputs'!J62,'Model inputs'!K62,'Model inputs'!L62,'Model inputs'!M62,'Model inputs'!N62,'Model inputs'!B62) -> 0
A6: 12-month cost of revenue | B6: =SUM('NeatRescue — Cash & scenarios ·'!B6,'NeatRescue — Cash & scenarios ·'!C6,'NeatRescue — Cash & scenarios ·'!D6,'NeatRescue — Cash & scenarios ·'!E6,'NeatRescue — Cash & scenarios ·'!F6,'NeatRescue — Cash & scenarios ·'!G6,'NeatRescue — Cash & scenarios ·'!H6,'NeatRescue — Cash & scenarios ·'!I6,'NeatRescue — Cash & scenarios ·'!J6,'NeatRescue — Cash & scenarios ·'!K6,'NeatRescue — Cash & scenarios ·'!L6,'NeatRescue — Cash & scenarios ·'!M6) -> 12404.905 | C6: =SUM('Model inputs'!D28,'Model inputs'!E28,'Model inputs'!F28,'Model inputs'!G28,'Model inputs'!H28,'Model inputs'!I28,'Model inputs'!J28,'Model inputs'!K28,'Model inputs'!L28,'Model inputs'!M28,'Model inputs'!N28,'Model inputs'!B28) -> 4741.6743 | D6: =SUM('Model inputs'!D26,'Model inputs'!E26,'Model inputs'!F26,'Model inputs'!G26,'Model inputs'!H26,'Model inputs'!I26,'Model inputs'!J26,'Model inputs'!K26,'Model inputs'!L26,'Model inputs'!M26,'Model inputs'!N26,'Model inputs'!B26) -> 28349.568 | E6: =SUM('Model inputs'!D27,'Model inputs'!E27,'Model inputs'!F27,'Model inputs'!G27,'Model inputs'!H27,'Model inputs'!I27,'Model inputs'!J27,'Model inputs'!K27,'Model inputs'!L27,'Model inputs'!M27,'Model inputs'!N27,'Model inputs'!B27) -> 12404.905 | F6: =SUM('Model inputs'!D25,'Model inputs'!E25,'Model inputs'!F25,'Model inputs'!G25,'Model inputs'!H25,'Model inputs'!I25,'Model inputs'!J25,'Model inputs'!K25,'Model inputs'!L25,'Model inputs'!M25,'Model inputs'!N25,'Model inputs'!B25) -> 2700
A7: 12-month gross profit | B7: ='NeatRescue — Hackathon subm (2)'!B5-'NeatRescue — Hackathon subm (2)'!B6 -> 19244.74 | C7: ='NeatRescue — Hackathon subm (2)'!C5-'NeatRescue — Hackathon subm (2)'!C6 -> 2320.4586 | D7: ='NeatRescue — Hackathon subm (2)'!D5-'NeatRescue — Hackathon subm (2)'!D6 -> 55298.825 | E7: ='NeatRescue — Hackathon subm (2)'!E5-'NeatRescue — Hackathon subm (2)'!E6 -> 19244.74 | F7: ='NeatRescue — Hackathon subm (2)'!F5-'NeatRescue — Hackathon subm (2)'!F6 -> -2700
A8: 12-month gross margin | B8: =IFERROR('NeatRescue — Hackathon subm (2)'!B7/'NeatRescue — Hackathon subm (2)'!B5,"") -> 0.60805547 | C8: =IFERROR('NeatRescue — Hackathon subm (2)'!C7/'NeatRescue — Hackathon subm (2)'!C5,"") -> 0.32857759 | D8: =IFERROR('NeatRescue — Hackathon subm (2)'!D7/'NeatRescue — Hackathon subm (2)'!D5,"") -> 0.66108652 | E8: =IFERROR('NeatRescue — Hackathon subm (2)'!E7/'NeatRescue — Hackathon subm (2)'!E5,"") -> 0.60805547 | F8: =IFERROR('NeatRescue — Hackathon subm (2)'!F7/'NeatRescue — Hackathon subm (2)'!F5,"")
A9: 12-month operating expenses | B9: =SUM('NeatRescue — Cash & scenarios ·'!B13,'NeatRescue — Cash & scenarios ·'!C13,'NeatRescue — Cash & scenarios ·'!D13,'NeatRescue — Cash & scenarios ·'!E13,'NeatRescue — Cash & scenarios ·'!F13,'NeatRescue — Cash & scenarios ·'!G13,'NeatRescue — Cash & scenarios ·'!H13,'NeatRescue — Cash & scenarios ·'!I13,'NeatRescue — Cash & scenarios ·'!J13,'NeatRescue — Cash & scenarios ·'!K13,'NeatRescue — Cash & scenarios ·'!L13,'NeatRescue — Cash & scenarios ·'!M13) -> 2900 | C9: =SUM('Model inputs'!D52,'Model inputs'!E52,'Model inputs'!F52,'Model inputs'!G52,'Model inputs'!H52,'Model inputs'!I52,'Model inputs'!J52,'Model inputs'!K52,'Model inputs'!L52,'Model inputs'!M52,'Model inputs'!N52,'Model inputs'!B52) -> 2000 | D9: =SUM('Model inputs'!D50,'Model inputs'!E50,'Model inputs'!F50,'Model inputs'!G50,'Model inputs'!H50,'Model inputs'!I50,'Model inputs'!J50,'Model inputs'!K50,'Model inputs'!L50,'Model inputs'!M50,'Model inputs'!N50,'Model inputs'!B50) -> 4700 | E9: =SUM('Model inputs'!D51,'Model inputs'!E51,'Model inputs'!F51,'Model inputs'!G51,'Model inputs'!H51,'Model inputs'!I51,'Model inputs'!J51,'Model inputs'!K51,'Model inputs'!L51,'Model inputs'!M51,'Model inputs'!N51,'Model inputs'!B51) -> 2900 | F9: =SUM('Model inputs'!D49,'Model inputs'!E49,'Model inputs'!F49,'Model inputs'!G49,'Model inputs'!H49,'Model inputs'!I49,'Model inputs'!J49,'Model inputs'!K49,'Model inputs'!L49,'Model inputs'!M49,'Model inputs'!N49,'Model inputs'!B49) -> 2900
A10: 12-month operating profit | B10: ='NeatRescue — Hackathon subm (2)'!B7-'NeatRescue — Hackathon subm (2)'!B9 -> 16344.74 | C10: ='NeatRescue — Hackathon subm (2)'!C7-'NeatRescue — Hackathon subm (2)'!C9 -> 320.45863 | D10: ='NeatRescue — Hackathon subm (2)'!D7-'NeatRescue — Hackathon subm (2)'!D9 -> 50598.825 | E10: ='NeatRescue — Hackathon subm (2)'!E7-'NeatRescue — Hackathon subm (2)'!E9 -> 16344.74 | F10: ='NeatRescue — Hackathon subm (2)'!F7-'NeatRescue — Hackathon subm (2)'!F9 -> -5600
A11: Month 12 customers | B11: =IF('NeatRescue — Revenue & costs ·'!M14="","",'NeatRescue — Revenue & costs ·'!M14) -> 51.961366 | C11: =IF('Model inputs'!B23="","",'Model inputs'!B23) -> 12.023801 | D11: =IF('Model inputs'!B21="","",'Model inputs'!B21) -> 155.21359 | E11: =IF('Model inputs'!B22="","",'Model inputs'!B22) -> 51.961366 | F11: =IF('Model inputs'!B20="","",'Model inputs'!B20) -> 0
A12: Month 12 revenue | B12: =IF('NeatRescue — Hackathon subm (3)'!M5="","",'NeatRescue — Hackathon subm (3)'!M5) -> 5559.8661 | C12: =IF('NeatRescue — Hackathon subm (3)'!M6="","",'NeatRescue — Hackathon subm (3)'!M6) -> 1017.2136 | D12: =IF('NeatRescue — Hackathon subm (3)'!M7="","",'NeatRescue — Hackathon subm (3)'!M7) -> 16607.854 | E12: =IF('Model inputs'!B67="","",'Model inputs'!B67) -> 5559.8661 | F12: =IF('Model inputs'!B62="","",'Model inputs'!B62) -> 0
A13: Month 12 gross margin | B13: =IF('NeatRescue — Cash & scenarios ·'!M8="","",'NeatRescue — Cash & scenarios ·'!M8) -> 0.65289589 | C13: =IF('Model inputs'!B38="","",'Model inputs'!B38) -> 0.48970586 | D13: =IF('Model inputs'!B36="","",'Model inputs'!B36) -> 0.67981668 | E13: =IF('Model inputs'!B37="","",'Model inputs'!B37) -> 0.65289589 | F13: =IF('Model inputs'!B35="","",'Model inputs'!B35)
A14: Month 12 operating profit | B14: =IF('NeatRescue — Hackathon subm (3)'!M8="","",'NeatRescue — Hackathon subm (3)'!M8) -> 3405.0137 | C14: =IF('NeatRescue — Hackathon subm (3)'!M9="","",'NeatRescue — Hackathon subm (3)'!M9) -> 348.13545 | D14: =IF('NeatRescue — Hackathon subm (3)'!M10="","",'NeatRescue — Hackathon subm (3)'!M10) -> 10915.296 | E14: =IF('Model inputs'!B56="","",'Model inputs'!B56) -> 3405.0137 | F14: =IF('Model inputs'!B54="","",'Model inputs'!B54) -> -450
A15: Month 12 cash | B15: =IF('NeatRescue — Cash & scenarios ·'!M17="","",'NeatRescue — Cash & scenarios ·'!M17) -> 16344.74 | C15: =IF('Model inputs'!B15="","",'Model inputs'!B15) -> 320.45863 | D15: =IF('Model inputs'!B13="","",'Model inputs'!B13) -> 50598.825 | E15: =IF('NeatRescue — Cash & scenari (2)'!M6="","",'NeatRescue — Cash & scenari (2)'!M6) -> 21344.74 | F15: =IF('NeatRescue — Cash & scenari (2)'!M7="","",'NeatRescue — Cash & scenari (2)'!M7) -> -600
A16: Peak funding gap | B16: =MAX('NeatRescue — Cash & scenarios ·'!B18,'NeatRescue — Cash & scenarios ·'!C18,'NeatRescue — Cash & scenarios ·'!D18,'NeatRescue — Cash & scenarios ·'!E18,'NeatRescue — Cash & scenarios ·'!F18,'NeatRescue — Cash & scenarios ·'!G18,'NeatRescue — Cash & scenarios ·'!H18,'NeatRescue — Cash & scenarios ·'!I18,'NeatRescue — Cash & scenarios ·'!J18,'NeatRescue — Cash & scenarios ·'!K18,'NeatRescue — Cash & scenarios ·'!L18,'NeatRescue — Cash & scenarios ·'!M18) -> 427.43 | C16: =MAX('Model inputs'!D33,'Model inputs'!E33,'Model inputs'!F33,'Model inputs'!G33,'Model inputs'!H33,'Model inputs'!I33,'Model inputs'!J33,'Model inputs'!K33,'Model inputs'!L33,'Model inputs'!M33,'Model inputs'!N33,'Model inputs'!B33) -> 1017.1518 | D16: =MAX('Model inputs'!D31,'Model inputs'!E31,'Model inputs'!F31,'Model inputs'!G31,'Model inputs'!H31,'Model inputs'!I31,'Model inputs'!J31,'Model inputs'!K31,'Model inputs'!L31,'Model inputs'!M31,'Model inputs'!N31,'Model inputs'!B31) -> 354.86 | E16: =MAX('Model inputs'!D32,'Model inputs'!E32,'Model inputs'!F32,'Model inputs'!G32,'Model inputs'!H32,'Model inputs'!I32,'Model inputs'!J32,'Model inputs'!K32,'Model inputs'!L32,'Model inputs'!M32,'Model inputs'!N32,'Model inputs'!B32) -> 0 | F16: =MAX('Model inputs'!D30,'Model inputs'!E30,'Model inputs'!F30,'Model inputs'!G30,'Model inputs'!H30,'Model inputs'!I30,'Model inputs'!J30,'Model inputs'!K30,'Model inputs'!L30,'Model inputs'!M30,'Model inputs'!N30,'Model inputs'!B30) -> 600
A17: Lowest projected cash | B17: =MIN('NeatRescue — Cash & scenarios ·'!B17,'NeatRescue — Cash & scenarios ·'!C17,'NeatRescue — Cash & scenarios ·'!D17,'NeatRescue — Cash & scenarios ·'!E17,'NeatRescue — Cash & scenarios ·'!F17,'NeatRescue — Cash & scenarios ·'!G17,'NeatRescue — Cash & scenarios ·'!H17,'NeatRescue — Cash & scenarios ·'!I17,'NeatRescue — Cash & scenarios ·'!J17,'NeatRescue — Cash & scenarios ·'!K17,'NeatRescue — Cash & scenarios ·'!L17,'NeatRescue — Cash & scenarios ·'!M17) -> -427.43 | C17: =MIN('Model inputs'!D15,'Model inputs'!E15,'Model inputs'!F15,'Model inputs'!G15,'Model inputs'!H15,'Model inputs'!I15,'Model inputs'!J15,'Model inputs'!K15,'Model inputs'!L15,'Model inputs'!M15,'Model inputs'!N15,'Model inputs'!B15) -> -1017.1518 | D17: =MIN('Model inputs'!D13,'Model inputs'!E13,'Model inputs'!F13,'Model inputs'!G13,'Model inputs'!H13,'Model inputs'!I13,'Model inputs'!J13,'Model inputs'!K13,'Model inputs'!L13,'Model inputs'!M13,'Model inputs'!N13,'Model inputs'!B13) -> -354.86 | E17: =MIN('NeatRescue — Cash & scenari (2)'!B6,'NeatRescue — Cash & scenari (2)'!C6,'NeatRescue — Cash & scenari (2)'!D6,'NeatRescue — Cash & scenari (2)'!E6,'NeatRescue — Cash & scenari (2)'!F6,'NeatRescue — Cash & scenari (2)'!G6,'NeatRescue — Cash & scenari (2)'!H6,'NeatRescue — Cash & scenari (2)'!I6,'NeatRescue — Cash & scenari (2)'!J6,'NeatRescue — Cash & scenari (2)'!K6,'NeatRescue — Cash & scenari (2)'!L6,'NeatRescue — Cash & scenari (2)'!M6) -> 4572.57 | F17: =MIN('NeatRescue — Cash & scenari (2)'!B7,'NeatRescue — Cash & scenari (2)'!C7,'NeatRescue — Cash & scenari (2)'!D7,'NeatRescue — Cash & scenari (2)'!E7,'NeatRescue — Cash & scenari (2)'!F7,'NeatRescue — Cash & scenari (2)'!G7,'NeatRescue — Cash & scenari (2)'!H7,'NeatRescue — Cash & scenari (2)'!I7,'NeatRescue — Cash & scenari (2)'!J7,'NeatRescue — Cash & scenari (2)'!K7,'NeatRescue — Cash & scenari (2)'!L7,'NeatRescue — Cash & scenari (2)'!M7) -> -600
A18: Month 12 break-even customers | B18: =IF('NeatRescue — Cash & scenarios ·'!M21="","",'NeatRescue — Cash & scenarios ·'!M21) -> 7 | C18: =IF('Model inputs'!B10="","",'Model inputs'!B10) -> 7 | D18: =IF('Model inputs'!B8="","",'Model inputs'!B8) -> 9 | E18: =IF('Model inputs'!B9="","",'Model inputs'!B9) -> 7 | F18: =IF('Model inputs'!B7="","",'Model inputs'!B7)

Sheet NeatRescue — Hackathon subm (3)
A1: NeatRescue — Hackathon submission · Monthly revenue & operating profit — three cases
A2: Financial model (5 pages) · Main Scenario
A4: Variable / dimension | B4: 2026-10 | C4: 2026-11 | D4: 2026-12 | E4: 2027-01 | F4: 2027-02 | G4: 2027-03 | H4: 2027-04 | I4: 2027-05 | J4: 2027-06 | K4: 2027-07 | L4: 2027-08 | M4: 2027-09
A5: Revenue | B5: =SUM('NeatRescue — Revenue & costs ·'!B27,'NeatRescue — Revenue & costs ·'!B28) -> 321 | C5: =SUM('NeatRescue — Revenue & costs ·'!C27,'NeatRescue — Revenue & costs ·'!C28) -> 658.05 | D5: =SUM('NeatRescue — Revenue & costs ·'!D27,'NeatRescue — Revenue & costs ·'!D28) -> 1013.5575 | E5: =SUM('NeatRescue — Revenue & costs ·'!E27,'NeatRescue — Revenue & costs ·'!E28) -> 1390.1306 | F5: =SUM('NeatRescue — Revenue & costs ·'!F27,'NeatRescue — Revenue & costs ·'!F28) -> 1790.6002 | G5: =SUM('NeatRescue — Revenue & costs ·'!G27,'NeatRescue — Revenue & costs ·'!G28) -> 2218.0439 | H5: =SUM('NeatRescue — Revenue & costs ·'!H27,'NeatRescue — Revenue & costs ·'!H28) -> 2675.8128 | I5: =SUM('NeatRescue — Revenue & costs ·'!I27,'NeatRescue — Revenue & costs ·'!I28) -> 3167.5603 | ... M5: =SUM('NeatRescue — Revenue & costs ·'!M27,'NeatRescue — Revenue & costs ·'!M28) -> 5559.8661
A6: Revenue > Conservative | B6: =SUM('Model inputs'!D70,'Model inputs'!D71) -> 105.75 | C6: =SUM('Model inputs'!E70,'Model inputs'!E71) -> 206.2125 | D6: =SUM('Model inputs'!F70,'Model inputs'!F71) -> 301.90568 | E6: =SUM('Model inputs'!G70,'Model inputs'!G71) -> 393.3091 | F6: =SUM('Model inputs'!H70,'Model inputs'!H71) -> 480.86693 | G6: =SUM('Model inputs'!I70,'Model inputs'!I71) -> 564.99081 | H6: =SUM('Model inputs'!J70,'Model inputs'!J71) -> 646.06257 | I6: =SUM('Model inputs'!K70,'Model inputs'!K71) -> 724.43673 | ... L6: =SUM('Model inputs'!N70,'Model inputs'!N71) -> 946.55526 | M6: =SUM('Model inputs'!B70,'Model inputs'!B71) -> 1017.2136
A7: Revenue > Growth | B7: =SUM('Model inputs'!D65,'Model inputs'!D66) -> 642 | C7: =SUM('Model inputs'!E65,'Model inputs'!E66) -> 1361.04 | D7: =SUM('Model inputs'!F65,'Model inputs'!F66) -> 2169.2538 | E7: =SUM('Model inputs'!G65,'Model inputs'!G66) -> 3080.5779 | F7: =SUM('Model inputs'!H65,'Model inputs'!H66) -> 4111.0226 | G7: =SUM('Model inputs'!I65,'Model inputs'!I66) -> 5278.9832 | H7: =SUM('Model inputs'!J65,'Model inputs'!J66) -> 6605.5988 | I7: =SUM('Model inputs'!K65,'Model inputs'!K66) -> 8115.1636 | ... L7: =SUM('Model inputs'!N65,'Model inputs'!N66) -> 14042.288 | M7: =SUM('Model inputs'!B65,'Model inputs'!B66) -> 16607.854
A8: Operating profit | B8: ='NeatRescue — Cash & scenarios ·'!B7-'NeatRescue — Cash & scenarios ·'!B13 -> -427.43 | C8: ='NeatRescue — Cash & scenarios ·'!C7-'NeatRescue — Cash & scenarios ·'!C13 -> 6.2685 | D8: ='NeatRescue — Cash & scenarios ·'!D7-'NeatRescue — Cash & scenarios ·'!D13 -> 252.76478 | E8: ='NeatRescue — Cash & scenarios ·'!E7-'NeatRescue — Cash & scenarios ·'!E13 -> 513.86721 | F8: ='NeatRescue — Cash & scenarios ·'!F7-'NeatRescue — Cash & scenarios ·'!F13 -> 791.53858 | G8: ='NeatRescue — Cash & scenarios ·'!G7-'NeatRescue — Cash & scenarios ·'!G13 -> 1087.9129 | H8: ='NeatRescue — Cash & scenarios ·'!H7-'NeatRescue — Cash & scenarios ·'!H13 -> 1405.3136 | I8: ='NeatRescue — Cash & scenarios ·'!I7-'NeatRescue — Cash & scenarios ·'!I13 -> 1746.2738 | ... M8: ='NeatRescue — Cash & scenarios ·'!M7-'NeatRescue — Cash & scenarios ·'!M13 -> 3405.0137
A9: Operating profit > Conservative | B9: ='Model inputs'!D41-'Model inputs'!D52 -> -499.8225 | C9: ='Model inputs'!E41-'Model inputs'!E52 -> -228.40387 | D9: ='Model inputs'!F41-'Model inputs'!F52 -> -160.37576 | E9: ='Model inputs'!G41-'Model inputs'!G52 -> -95.397211 | F9: ='Model inputs'!H41-'Model inputs'!H52 -> -33.152495 | G9: ='Model inputs'!I41-'Model inputs'!I52 -> 26.651031 | H9: ='Model inputs'!J41-'Model inputs'!J52 -> 84.284815 | I9: ='Model inputs'!K41-'Model inputs'!K52 -> 140.00087 | ... L9: ='Model inputs'!N41-'Model inputs'!N52 -> 297.90457 | M9: ='Model inputs'!B41-'Model inputs'!B52 -> 348.13545
A10: Operating profit > Growth | B10: ='Model inputs'!D40-'Model inputs'!D50 -> -354.86 | C10: ='Model inputs'!E40-'Model inputs'!E50 -> 343.6968 | D10: ='Model inputs'!F40-'Model inputs'!F50 -> 904.08355 | E10: ='Model inputs'!G40-'Model inputs'!G50 -> 1535.9633 | F10: ='Model inputs'!H40-'Model inputs'!H50 -> 2250.4371 | G10: ='Model inputs'!I40-'Model inputs'!I50 -> 3060.2595 | H10: ='Model inputs'!J40-'Model inputs'!J50 -> 3980.0876 | I10: ='Model inputs'!K40-'Model inputs'!K50 -> 5026.7662 | ... L10: ='Model inputs'!N40-'Model inputs'!N50 -> 9136.4236 | M10: ='Model inputs'!B40-'Model inputs'!B50 -> 10915.296

Sheet NeatRescue — Assumptions & simu
A1: NeatRescue — Assumptions & simulator · Operating assumptions — hypothetical USD
A2: Financial model (5 pages) · Main Scenario
A4: Variable / dimension | B4: Value
A5: Monthly acquisition growth | B5: =0.1 -> 0.1
A6: Monthly customer churn | B6: =0.05 -> 0.05
A7: Inference cost per verification | B7: =0.05 -> 0.05
A8: Compute cost per verification | B8: =0.015 -> 0.015
A9: Logging cost per verification | B9: =0.005 -> 0.005
A10: Monthly hosting budget | B10: =60 -> 60
A11: Monthly compute baseline | B11: =40 -> 40
A12: Monthly logging baseline | B12: =25 -> 25
A13: Monthly security budget | B13: =75 -> 75
A14: Monthly support baseline | B14: =100 -> 100
A15: Monthly acquisition budget | B15: =150 -> 150
A16: Launch expense | B16: =200 -> 200
A17: Opening cash | B17: =0 -> 0
A18: Payment processing rate | B18: =0.03 -> 0.03
A19: Founder monthly pay | B19: =0 -> 0
A20: Minimum cash reserve | B20: =0 -> 0

Sheet NeatRescue — Assumptions & (2)
A1: NeatRescue — Assumptions & simulator · Pricing & acquisition assumptions — hypothetical
A2: Financial model (5 pages) · Main Scenario
A4: Variable / dimension | B4: Monthly subscription price | C4: Included verifications | D4: Verifications per customer | E4: Overage price per verification | F4: Support cost per customer | G4: First-month new customers
A5: Starter | B5: =49 -> 49 | C5: =100 -> 100 | D5: =120 -> 120 | E5: =0.1 -> 0.1 | F5: =2 -> 2 | G5: =2 -> 2
A6: Team | B6: =199 -> 199 | C6: =600 -> 600 | D6: =800 -> 800 | E6: =0.1 -> 0.1 | F6: =12 -> 12 | G6: =1 -> 1

Sheet NeatRescue — Assumptions & (3)
A1: NeatRescue — Assumptions & simulator · Per-customer contribution & usage price floor
A2: Financial model (5 pages) · Main Scenario
A4: Variable / dimension | B4: Effective monthly bill | C4: Verification unit cost | D4: Unit contribution per customer | E4: Unit contribution percentage | F4: Usage inference break-even ceiling | G4: Minimum usage price at cost
A5: Starter | B5: ='NeatRescue — Assumptions & (2)'!B5+MAX('NeatRescue — Assumptions & (2)'!D5-'NeatRescue — Assumptions & (2)'!C5,0)*'NeatRescue — Assumptions & (2)'!E5 -> 51 | C5: ='NeatRescue — Assumptions & simu'!B7+'NeatRescue — Assumptions & simu'!B8+'NeatRescue — Assumptions & simu'!B9 -> 0.07 | D5: ='NeatRescue — Assumptions & (3)'!B5*(1-'NeatRescue — Assumptions & simu'!B18)-'NeatRescue — Assumptions & (2)'!D5*'NeatRescue — Assumptions & (3)'!C5-'NeatRescue — Assumptions & (2)'!F5 -> 39.07 | E5: =IFERROR('NeatRescue — Assumptions & (3)'!D5/'NeatRescue — Assumptions & (3)'!B5,"") -> 0.76607843 | F5: ='NeatRescue — Assumptions & (2)'!E5*(1-'NeatRescue — Assumptions & simu'!B18)-'NeatRescue — Assumptions & simu'!B8-'NeatRescue — Assumptions & simu'!B9 -> 0.077 | G5: =IFERROR('NeatRescue — Assumptions & (3)'!C5/(1-'NeatRescue — Assumptions & simu'!B18),"") -> 0.072164948
A6: Team | B6: ='NeatRescue — Assumptions & (2)'!B6+MAX('NeatRescue — Assumptions & (2)'!D6-'NeatRescue — Assumptions & (2)'!C6,0)*'NeatRescue — Assumptions & (2)'!E6 -> 219 | C6: ='NeatRescue — Assumptions & simu'!B7+'NeatRescue — Assumptions & simu'!B8+'NeatRescue — Assumptions & simu'!B9 -> 0.07 | D6: ='NeatRescue — Assumptions & (3)'!B6*(1-'NeatRescue — Assumptions & simu'!B18)-'NeatRescue — Assumptions & (2)'!D6*'NeatRescue — Assumptions & (3)'!C6-'NeatRescue — Assumptions & (2)'!F6 -> 144.43 | E6: =IFERROR('NeatRescue — Assumptions & (3)'!D6/'NeatRescue — Assumptions & (3)'!B6,"") -> 0.65949772 | F6: ='NeatRescue — Assumptions & (2)'!E6*(1-'NeatRescue — Assumptions & simu'!B18)-'NeatRescue — Assumptions & simu'!B8-'NeatRescue — Assumptions & simu'!B9 -> 0.077 | G6: =IFERROR('NeatRescue — Assumptions & (3)'!C6/(1-'NeatRescue — Assumptions & simu'!B18),"") -> 0.072164948

Sheet NeatRescue — Revenue & costs ·
A1: NeatRescue — Revenue & costs · Customers, usage & unit economics
A2: Financial model (5 pages) · Main Scenario
A4: Variable / dimension | B4: 2026-10 | C4: 2026-11 | D4: 2026-12 | E4: 2027-01 | F4: 2027-02 | G4: 2027-03 | H4: 2027-04 | I4: 2027-05 | J4: 2027-06 | K4: 2027-07 | L4: 2027-08 | M4: 2027-09
A5: New customers | B5: =SUM('NeatRescue — Revenue & costs ·'!B6,'NeatRescue — Revenue & costs ·'!B7) -> 3 | C5: =SUM('NeatRescue — Revenue & costs ·'!C6,'NeatRescue — Revenue & costs ·'!C7) -> 3.3 | D5: =SUM('NeatRescue — Revenue & costs ·'!D6,'NeatRescue — Revenue & costs ·'!D7) -> 3.63 | E5: =SUM('NeatRescue — Revenue & costs ·'!E6,'NeatRescue — Revenue & costs ·'!E7) -> 3.993 | F5: =SUM('NeatRescue — Revenue & costs ·'!F6,'NeatRescue — Revenue & costs ·'!F7) -> 4.3923 | G5: =SUM('NeatRescue — Revenue & costs ·'!G6,'NeatRescue — Revenue & costs ·'!G7) -> 4.83153 | H5: =SUM('NeatRescue — Revenue & costs ·'!H6,'NeatRescue — Revenue & costs ·'!H7) -> 5.314683 | I5: =SUM('NeatRescue — Revenue & costs ·'!I6,'NeatRescue — Revenue & costs ·'!I7) -> 5.8461513 | ... M5: =SUM('NeatRescue — Revenue & costs ·'!M6,'NeatRescue — Revenue & costs ·'!M7) -> 8.5593501
A6: Starter | B6: =IF('NeatRescue — Assumptions & (2)'!G5="","",'NeatRescue — Assumptions & (2)'!G5) -> 2 | C6: ='NeatRescue — Revenue & costs ·'!B6*(1+'NeatRescue — Assumptions & simu'!B5) -> 2.2 | D6: ='NeatRescue — Revenue & costs ·'!C6*(1+'NeatRescue — Assumptions & simu'!B5) -> 2.42 | E6: ='NeatRescue — Revenue & costs ·'!D6*(1+'NeatRescue — Assumptions & simu'!B5) -> 2.662 | F6: ='NeatRescue — Revenue & costs ·'!E6*(1+'NeatRescue — Assumptions & simu'!B5) -> 2.9282 | G6: ='NeatRescue — Revenue & costs ·'!F6*(1+'NeatRescue — Assumptions & simu'!B5) -> 3.22102 | H6: ='NeatRescue — Revenue & costs ·'!G6*(1+'NeatRescue — Assumptions & simu'!B5) -> 3.543122 | I6: ='NeatRescue — Revenue & costs ·'!H6*(1+'NeatRescue — Assumptions & simu'!B5) -> 3.8974342 | J6: ='NeatRescue — Revenue & costs ·'!I6*(1+'NeatRescue — Assumptions & simu'!B5) -> 4.2871776 | K6: ='NeatRescue — Revenue & costs ·'!J6*(1+'NeatRescue — Assumptions & simu'!B5) -> 4.7158954 | L6: ='NeatRescue — Revenue & costs ·'!K6*(1+'NeatRescue — Assumptions & simu'!B5) -> 5.1874849 | M6: ='NeatRescue — Revenue & costs ·'!L6*(1+'NeatRescue — Assumptions & simu'!B5) -> 5.7062334
A7: Team | B7: =IF('NeatRescue — Assumptions & (2)'!G6="","",'NeatRescue — Assumptions & (2)'!G6) -> 1 | C7: ='NeatRescue — Revenue & costs ·'!B7*(1+'NeatRescue — Assumptions & simu'!B5) -> 1.1 | D7: ='NeatRescue — Revenue & costs ·'!C7*(1+'NeatRescue — Assumptions & simu'!B5) -> 1.21 | E7: ='NeatRescue — Revenue & costs ·'!D7*(1+'NeatRescue — Assumptions & simu'!B5) -> 1.331 | F7: ='NeatRescue — Revenue & costs ·'!E7*(1+'NeatRescue — Assumptions & simu'!B5) -> 1.4641 | G7: ='NeatRescue — Revenue & costs ·'!F7*(1+'NeatRescue — Assumptions & simu'!B5) -> 1.61051 | H7: ='NeatRescue — Revenue & costs ·'!G7*(1+'NeatRescue — Assumptions & simu'!B5) -> 1.771561 | I7: ='NeatRescue — Revenue & costs ·'!H7*(1+'NeatRescue — Assumptions & simu'!B5) -> 1.9487171 | J7: ='NeatRescue — Revenue & costs ·'!I7*(1+'NeatRescue — Assumptions & simu'!B5) -> 2.1435888 | K7: ='NeatRescue — Revenue & costs ·'!J7*(1+'NeatRescue — Assumptions & simu'!B5) -> 2.3579477 | L7: ='NeatRescue — Revenue & costs ·'!K7*(1+'NeatRescue — Assumptions & simu'!B5) -> 2.5937425 | M7: ='NeatRescue — Revenue & costs ·'!L7*(1+'NeatRescue — Assumptions & simu'!B5) -> 2.8531167
A8: Opening customers | B8: =SUM('NeatRescue — Revenue & costs ·'!B9,'NeatRescue — Revenue & costs ·'!B10) -> 0 | C8: =SUM('NeatRescue — Revenue & costs ·'!C9,'NeatRescue — Revenue & costs ·'!C10) -> 3 | D8: =SUM('NeatRescue — Revenue & costs ·'!D9,'NeatRescue — Revenue & costs ·'!D10) -> 6.15 | E8: =SUM('NeatRescue — Revenue & costs ·'!E9,'NeatRescue — Revenue & costs ·'!E10) -> 9.4725 | F8: =SUM('NeatRescue — Revenue & costs ·'!F9,'NeatRescue — Revenue & costs ·'!F10) -> 12.991875 | G8: =SUM('NeatRescue — Revenue & costs ·'!G9,'NeatRescue — Revenue & costs ·'!G10) -> 16.734581 | H8: =SUM('NeatRescue — Revenue & costs ·'!H9,'NeatRescue — Revenue & costs ·'!H10) -> 20.729382 | I8: =SUM('NeatRescue — Revenue & costs ·'!I9,'NeatRescue — Revenue & costs ·'!I10) -> 25.007596 | ... M8: =SUM('NeatRescue — Revenue & costs ·'!M9,'NeatRescue — Revenue & costs ·'!M10) -> 45.686332
A9: Starter | B9: =IF('Model inputs'!C18="","",'Model inputs'!C18) -> 0 | C9: =IF('NeatRescue — Revenue & costs ·'!B15="","",'NeatRescue — Revenue & costs ·'!B15) -> 2 | D9: =IF('NeatRescue — Revenue & costs ·'!C15="","",'NeatRescue — Revenue & costs ·'!C15) -> 4.1 | E9: =IF('NeatRescue — Revenue & costs ·'!D15="","",'NeatRescue — Revenue & costs ·'!D15) -> 6.315 | F9: =IF('NeatRescue — Revenue & costs ·'!E15="","",'NeatRescue — Revenue & costs ·'!E15) -> 8.66125 | G9: =IF('NeatRescue — Revenue & costs ·'!F15="","",'NeatRescue — Revenue & costs ·'!F15) -> 11.156388 | H9: =IF('NeatRescue — Revenue & costs ·'!G15="","",'NeatRescue — Revenue & costs ·'!G15) -> 13.819588 | I9: =IF('NeatRescue — Revenue & costs ·'!H15="","",'NeatRescue — Revenue & costs ·'!H15) -> 16.671731 | J9: =IF('NeatRescue — Revenue & costs ·'!I15="","",'NeatRescue — Revenue & costs ·'!I15) -> 19.735578 | ... M9: =IF('NeatRescue — Revenue & costs ·'!L15="","",'NeatRescue — Revenue & costs ·'!L15) -> 30.457555
A10: Team | B10: =IF('Model inputs'!C19="","",'Model inputs'!C19) -> 0 | C10: =IF('NeatRescue — Revenue & costs ·'!B16="","",'NeatRescue — Revenue & costs ·'!B16) -> 1 | D10: =IF('NeatRescue — Revenue & costs ·'!C16="","",'NeatRescue — Revenue & costs ·'!C16) -> 2.05 | E10: =IF('NeatRescue — Revenue & costs ·'!D16="","",'NeatRescue — Revenue & costs ·'!D16) -> 3.1575 | F10: =IF('NeatRescue — Revenue & costs ·'!E16="","",'NeatRescue — Revenue & costs ·'!E16) -> 4.330625 | G10: =IF('NeatRescue — Revenue & costs ·'!F16="","",'NeatRescue — Revenue & costs ·'!F16) -> 5.5781938 | H10: =IF('NeatRescue — Revenue & costs ·'!G16="","",'NeatRescue — Revenue & costs ·'!G16) -> 6.9097941 | I10: =IF('NeatRescue — Revenue & costs ·'!H16="","",'NeatRescue — Revenue & costs ·'!H16) -> 8.3358654 | J10: =IF('NeatRescue — Revenue & costs ·'!I16="","",'NeatRescue — Revenue & costs ·'!I16) -> 9.8677892 | ... M10: =IF('NeatRescue — Revenue & costs ·'!L16="","",'NeatRescue — Revenue & costs ·'!L16) -> 15.228777
A11: Churned customers | B11: =SUM('NeatRescue — Revenue & costs ·'!B12,'NeatRescue — Revenue & costs ·'!B13) -> 0 | C11: =SUM('NeatRescue — Revenue & costs ·'!C12,'NeatRescue — Revenue & costs ·'!C13) -> 0.15 | D11: =SUM('NeatRescue — Revenue & costs ·'!D12,'NeatRescue — Revenue & costs ·'!D13) -> 0.3075 | E11: =SUM('NeatRescue — Revenue & costs ·'!E12,'NeatRescue — Revenue & costs ·'!E13) -> 0.473625 | F11: =SUM('NeatRescue — Revenue & costs ·'!F12,'NeatRescue — Revenue & costs ·'!F13) -> 0.64959375 | G11: =SUM('NeatRescue — Revenue & costs ·'!G12,'NeatRescue — Revenue & costs ·'!G13) -> 0.83672906 | H11: =SUM('NeatRescue — Revenue & costs ·'!H12,'NeatRescue — Revenue & costs ·'!H13) -> 1.0364691 | I11: =SUM('NeatRescue — Revenue & costs ·'!I12,'NeatRescue — Revenue & costs ·'!I13) -> 1.2503798 | ... M11: =SUM('NeatRescue — Revenue & costs ·'!M12,'NeatRescue — Revenue & costs ·'!M13) -> 2.2843166
A12: Starter | B12: ='NeatRescue — Revenue & costs ·'!B9*'NeatRescue — Assumptions & simu'!B6 -> 0 | C12: ='NeatRescue — Revenue & costs ·'!C9*'NeatRescue — Assumptions & simu'!B6 -> 0.1 | D12: ='NeatRescue — Revenue & costs ·'!D9*'NeatRescue — Assumptions & simu'!B6 -> 0.205 | E12: ='NeatRescue — Revenue & costs ·'!E9*'NeatRescue — Assumptions & simu'!B6 -> 0.31575 | F12: ='NeatRescue — Revenue & costs ·'!F9*'NeatRescue — Assumptions & simu'!B6 -> 0.4330625 | G12: ='NeatRescue — Revenue & costs ·'!G9*'NeatRescue — Assumptions & simu'!B6 -> 0.55781938 | H12: ='NeatRescue — Revenue & costs ·'!H9*'NeatRescue — Assumptions & simu'!B6 -> 0.69097941 | I12: ='NeatRescue — Revenue & costs ·'!I9*'NeatRescue — Assumptions & simu'!B6 -> 0.83358654 | J12: ='NeatRescue — Revenue & costs ·'!J9*'NeatRescue — Assumptions & simu'!B6 -> 0.98677892 | K12: ='NeatRescue — Revenue & costs ·'!K9*'NeatRescue — Assumptions & simu'!B6 -> 1.1517989 | L12: ='NeatRescue — Revenue & costs ·'!L9*'NeatRescue — Assumptions & simu'!B6 -> 1.3300037 | M12: ='NeatRescue — Revenue & costs ·'!M9*'NeatRescue — Assumptions & simu'!B6 -> 1.5228777
A13: Team | B13: ='NeatRescue — Revenue & costs ·'!B10*'NeatRescue — Assumptions & simu'!B6 -> 0 | C13: ='NeatRescue — Revenue & costs ·'!C10*'NeatRescue — Assumptions & simu'!B6 -> 0.05 | D13: ='NeatRescue — Revenue & costs ·'!D10*'NeatRescue — Assumptions & simu'!B6 -> 0.1025 | E13: ='NeatRescue — Revenue & costs ·'!E10*'NeatRescue — Assumptions & simu'!B6 -> 0.157875 | F13: ='NeatRescue — Revenue & costs ·'!F10*'NeatRescue — Assumptions & simu'!B6 -> 0.21653125 | G13: ='NeatRescue — Revenue & costs ·'!G10*'NeatRescue — Assumptions & simu'!B6 -> 0.27890969 | H13: ='NeatRescue — Revenue & costs ·'!H10*'NeatRescue — Assumptions & simu'!B6 -> 0.3454897 | I13: ='NeatRescue — Revenue & costs ·'!I10*'NeatRescue — Assumptions & simu'!B6 -> 0.41679327 | J13: ='NeatRescue — Revenue & costs ·'!J10*'NeatRescue — Assumptions & simu'!B6 -> 0.49338946 | K13: ='NeatRescue — Revenue & costs ·'!K10*'NeatRescue — Assumptions & simu'!B6 -> 0.57589943 | L13: ='NeatRescue — Revenue & costs ·'!L10*'NeatRescue — Assumptions & simu'!B6 -> 0.66500184 | M13: ='NeatRescue — Revenue & costs ·'!M10*'NeatRescue — Assumptions & simu'!B6 -> 0.76143887
A14: Closing customers | B14: =SUM('NeatRescue — Revenue & costs ·'!B15,'NeatRescue — Revenue & costs ·'!B16) -> 3 | C14: =SUM('NeatRescue — Revenue & costs ·'!C15,'NeatRescue — Revenue & costs ·'!C16) -> 6.15 | D14: =SUM('NeatRescue — Revenue & costs ·'!D15,'NeatRescue — Revenue & costs ·'!D16) -> 9.4725 | E14: =SUM('NeatRescue — Revenue & costs ·'!E15,'NeatRescue — Revenue & costs ·'!E16) -> 12.991875 | F14: =SUM('NeatRescue — Revenue & costs ·'!F15,'NeatRescue — Revenue & costs ·'!F16) -> 16.734581 | G14: =SUM('NeatRescue — Revenue & costs ·'!G15,'NeatRescue — Revenue & costs ·'!G16) -> 20.729382 | H14: =SUM('NeatRescue — Revenue & costs ·'!H15,'NeatRescue — Revenue & costs ·'!H16) -> 25.007596 | I14: =SUM('NeatRescue — Revenue & costs ·'!I15,'NeatRescue — Revenue & costs ·'!I16) -> 29.603368 | ... M14: =SUM('NeatRescue — Revenue & costs ·'!M15,'NeatRescue — Revenue & costs ·'!M16) -> 51.961366
A15: Starter | B15: ='NeatRescue — Revenue & costs ·'!B9+'NeatRescue — Revenue & costs ·'!B6-'NeatRescue — Revenue & costs ·'!B12 -> 2 | C15: ='NeatRescue — Revenue & costs ·'!C9+'NeatRescue — Revenue & costs ·'!C6-'NeatRescue — Revenue & costs ·'!C12 -> 4.1 | D15: ='NeatRescue — Revenue & costs ·'!D9+'NeatRescue — Revenue & costs ·'!D6-'NeatRescue — Revenue & costs ·'!D12 -> 6.315 | E15: ='NeatRescue — Revenue & costs ·'!E9+'NeatRescue — Revenue & costs ·'!E6-'NeatRescue — Revenue & costs ·'!E12 -> 8.66125 | F15: ='NeatRescue — Revenue & costs ·'!F9+'NeatRescue — Revenue & costs ·'!F6-'NeatRescue — Revenue & costs ·'!F12 -> 11.156388 | G15: ='NeatRescue — Revenue & costs ·'!G9+'NeatRescue — Revenue & costs ·'!G6-'NeatRescue — Revenue & costs ·'!G12 -> 13.819588 | H15: ='NeatRescue — Revenue & costs ·'!H9+'NeatRescue — Revenue & costs ·'!H6-'NeatRescue — Revenue & costs ·'!H12 -> 16.671731 | I15: ='NeatRescue — Revenue & costs ·'!I9+'NeatRescue — Revenue & costs ·'!I6-'NeatRescue — Revenue & costs ·'!I12 -> 19.735578 | ... M15: ='NeatRescue — Revenue & costs ·'!M9+'NeatRescue — Revenue & costs ·'!M6-'NeatRescue — Revenue & costs ·'!M12 -> 34.640911
A16: Team | B16: ='NeatRescue — Revenue & costs ·'!B10+'NeatRescue — Revenue & costs ·'!B7-'NeatRescue — Revenue & costs ·'!B13 -> 1 | C16: ='NeatRescue — Revenue & costs ·'!C10+'NeatRescue — Revenue & costs ·'!C7-'NeatRescue — Revenue & costs ·'!C13 -> 2.05 | D16: ='NeatRescue — Revenue & costs ·'!D10+'NeatRescue — Revenue & costs ·'!D7-'NeatRescue — Revenue & costs ·'!D13 -> 3.1575 | E16: ='NeatRescue — Revenue & costs ·'!E10+'NeatRescue — Revenue & costs ·'!E7-'NeatRescue — Revenue & costs ·'!E13 -> 4.330625 | F16: ='NeatRescue — Revenue & costs ·'!F10+'NeatRescue — Revenue & costs ·'!F7-'NeatRescue — Revenue & costs ·'!F13 -> 5.5781938 | G16: ='NeatRescue — Revenue & costs ·'!G10+'NeatRescue — Revenue & costs ·'!G7-'NeatRescue — Revenue & costs ·'!G13 -> 6.9097941 | H16: ='NeatRescue — Revenue & costs ·'!H10+'NeatRescue — Revenue & costs ·'!H7-'NeatRescue — Revenue & costs ·'!H13 -> 8.3358654 | I16: ='NeatRescue — Revenue & costs ·'!I10+'NeatRescue — Revenue & costs ·'!I7-'NeatRescue — Revenue & costs ·'!I13 -> 9.8677892 | ... M16: ='NeatRescue — Revenue & costs ·'!M10+'NeatRescue — Revenue & costs ·'!M7-'NeatRescue — Revenue & costs ·'!M13 -> 17.320455
A17: Billed verifications | B17: =SUM('NeatRescue — Revenue & costs ·'!B18,'NeatRescue — Revenue & costs ·'!B19) -> 1040 | C17: =SUM('NeatRescue — Revenue & costs ·'!C18,'NeatRescue — Revenue & costs ·'!C19) -> 2132 | D17: =SUM('NeatRescue — Revenue & costs ·'!D18,'NeatRescue — Revenue & costs ·'!D19) -> 3283.8 | E17: =SUM('NeatRescue — Revenue & costs ·'!E18,'NeatRescue — Revenue & costs ·'!E19) -> 4503.85 | F17: =SUM('NeatRescue — Revenue & costs ·'!F18,'NeatRescue — Revenue & costs ·'!F19) -> 5801.3215 | G17: =SUM('NeatRescue — Revenue & costs ·'!G18,'NeatRescue — Revenue & costs ·'!G19) -> 7186.1858 | H17: =SUM('NeatRescue — Revenue & costs ·'!H18,'NeatRescue — Revenue & costs ·'!H19) -> 8669.3 | I17: =SUM('NeatRescue — Revenue & costs ·'!I18,'NeatRescue — Revenue & costs ·'!I19) -> 10262.501 | ... M17: =SUM('NeatRescue — Revenue & costs ·'!M18,'NeatRescue — Revenue & costs ·'!M19) -> 18013.273
A18: Starter | B18: ='NeatRescue — Revenue & costs ·'!B15*'NeatRescue — Assumptions & (2)'!D5 -> 240 | C18: ='NeatRescue — Revenue & costs ·'!C15*'NeatRescue — Assumptions & (2)'!D5 -> 492 | D18: ='NeatRescue — Revenue & costs ·'!D15*'NeatRescue — Assumptions & (2)'!D5 -> 757.8 | E18: ='NeatRescue — Revenue & costs ·'!E15*'NeatRescue — Assumptions & (2)'!D5 -> 1039.35 | F18: ='NeatRescue — Revenue & costs ·'!F15*'NeatRescue — Assumptions & (2)'!D5 -> 1338.7665 | G18: ='NeatRescue — Revenue & costs ·'!G15*'NeatRescue — Assumptions & (2)'!D5 -> 1658.3506 | H18: ='NeatRescue — Revenue & costs ·'!H15*'NeatRescue — Assumptions & (2)'!D5 -> 2000.6077 | I18: ='NeatRescue — Revenue & costs ·'!I15*'NeatRescue — Assumptions & (2)'!D5 -> 2368.2694 | J18: ='NeatRescue — Revenue & costs ·'!J15*'NeatRescue — Assumptions & (2)'!D5 -> 2764.3173 | K18: ='NeatRescue — Revenue & costs ·'!K15*'NeatRescue — Assumptions & (2)'!D5 -> 3192.0088 | L18: ='NeatRescue — Revenue & costs ·'!L15*'NeatRescue — Assumptions & (2)'!D5 -> 3654.9066 | M18: ='NeatRescue — Revenue & costs ·'!M15*'NeatRescue — Assumptions & (2)'!D5 -> 4156.9093
A19: Team | B19: ='NeatRescue — Revenue & costs ·'!B16*'NeatRescue — Assumptions & (2)'!D6 -> 800 | C19: ='NeatRescue — Revenue & costs ·'!C16*'NeatRescue — Assumptions & (2)'!D6 -> 1640 | D19: ='NeatRescue — Revenue & costs ·'!D16*'NeatRescue — Assumptions & (2)'!D6 -> 2526 | E19: ='NeatRescue — Revenue & costs ·'!E16*'NeatRescue — Assumptions & (2)'!D6 -> 3464.5 | F19: ='NeatRescue — Revenue & costs ·'!F16*'NeatRescue — Assumptions & (2)'!D6 -> 4462.555 | G19: ='NeatRescue — Revenue & costs ·'!G16*'NeatRescue — Assumptions & (2)'!D6 -> 5527.8353 | H19: ='NeatRescue — Revenue & costs ·'!H16*'NeatRescue — Assumptions & (2)'!D6 -> 6668.6923 | I19: ='NeatRescue — Revenue & costs ·'!I16*'NeatRescue — Assumptions & (2)'!D6 -> 7894.2314 | J19: ='NeatRescue — Revenue & costs ·'!J16*'NeatRescue — Assumptions & (2)'!D6 -> 9214.3908 | K19: ='NeatRescue — Revenue & costs ·'!K16*'NeatRescue — Assumptions & (2)'!D6 -> 10640.029 | L19: ='NeatRescue — Revenue & costs ·'!L16*'NeatRescue — Assumptions & (2)'!D6 -> 12183.022 | M19: ='NeatRescue — Revenue & costs ·'!M16*'NeatRescue — Assumptions & (2)'!D6 -> 13856.364
A20: Subscription revenue | B20: =SUM('NeatRescue — Revenue & costs ·'!B21,'NeatRescue — Revenue & costs ·'!B22) -> 297 | C20: =SUM('NeatRescue — Revenue & costs ·'!C21,'NeatRescue — Revenue & costs ·'!C22) -> 608.85 | D20: =SUM('NeatRescue — Revenue & costs ·'!D21,'NeatRescue — Revenue & costs ·'!D22) -> 937.7775 | E20: =SUM('NeatRescue — Revenue & costs ·'!E21,'NeatRescue — Revenue & costs ·'!E22) -> 1286.1956 | F20: =SUM('NeatRescue — Revenue & costs ·'!F21,'NeatRescue — Revenue & costs ·'!F22) -> 1656.7235 | G20: =SUM('NeatRescue — Revenue & costs ·'!G21,'NeatRescue — Revenue & costs ·'!G22) -> 2052.2088 | H20: =SUM('NeatRescue — Revenue & costs ·'!H21,'NeatRescue — Revenue & costs ·'!H22) -> 2475.752 | I20: =SUM('NeatRescue — Revenue & costs ·'!I21,'NeatRescue — Revenue & costs ·'!I22) -> 2930.7334 | ... M20: =SUM('NeatRescue — Revenue & costs ·'!M21,'NeatRescue — Revenue & costs ·'!M22) -> 5144.1752
A21: Starter | B21: ='NeatRescue — Revenue & costs ·'!B15*'NeatRescue — Assumptions & (2)'!B5 -> 98 | C21: ='NeatRescue — Revenue & costs ·'!C15*'NeatRescue — Assumptions & (2)'!B5 -> 200.9 | D21: ='NeatRescue — Revenue & costs ·'!D15*'NeatRescue — Assumptions & (2)'!B5 -> 309.435 | E21: ='NeatRescue — Revenue & costs ·'!E15*'NeatRescue — Assumptions & (2)'!B5 -> 424.40125 | F21: ='NeatRescue — Revenue & costs ·'!F15*'NeatRescue — Assumptions & (2)'!B5 -> 546.66299 | G21: ='NeatRescue — Revenue & costs ·'!G15*'NeatRescue — Assumptions & (2)'!B5 -> 677.15982 | H21: ='NeatRescue — Revenue & costs ·'!H15*'NeatRescue — Assumptions & (2)'!B5 -> 816.91481 | I21: ='NeatRescue — Revenue & costs ·'!I15*'NeatRescue — Assumptions & (2)'!B5 -> 967.04334 | J21: ='NeatRescue — Revenue & costs ·'!J15*'NeatRescue — Assumptions & (2)'!B5 -> 1128.7629 | K21: ='NeatRescue — Revenue & costs ·'!K15*'NeatRescue — Assumptions & (2)'!B5 -> 1303.4036 | L21: ='NeatRescue — Revenue & costs ·'!L15*'NeatRescue — Assumptions & (2)'!B5 -> 1492.4202 | M21: ='NeatRescue — Revenue & costs ·'!M15*'NeatRescue — Assumptions & (2)'!B5 -> 1697.4046
A22: Team | B22: ='NeatRescue — Revenue & costs ·'!B16*'NeatRescue — Assumptions & (2)'!B6 -> 199 | C22: ='NeatRescue — Revenue & costs ·'!C16*'NeatRescue — Assumptions & (2)'!B6 -> 407.95 | D22: ='NeatRescue — Revenue & costs ·'!D16*'NeatRescue — Assumptions & (2)'!B6 -> 628.3425 | E22: ='NeatRescue — Revenue & costs ·'!E16*'NeatRescue — Assumptions & (2)'!B6 -> 861.79438 | F22: ='NeatRescue — Revenue & costs ·'!F16*'NeatRescue — Assumptions & (2)'!B6 -> 1110.0606 | G22: ='NeatRescue — Revenue & costs ·'!G16*'NeatRescue — Assumptions & (2)'!B6 -> 1375.049 | H22: ='NeatRescue — Revenue & costs ·'!H16*'NeatRescue — Assumptions & (2)'!B6 -> 1658.8372 | I22: ='NeatRescue — Revenue & costs ·'!I16*'NeatRescue — Assumptions & (2)'!B6 -> 1963.69 | J22: ='NeatRescue — Revenue & costs ·'!J16*'NeatRescue — Assumptions & (2)'!B6 -> 2292.0797 | K22: ='NeatRescue — Revenue & costs ·'!K16*'NeatRescue — Assumptions & (2)'!B6 -> 2646.7073 | L22: ='NeatRescue — Revenue & costs ·'!L16*'NeatRescue — Assumptions & (2)'!B6 -> 3030.5267 | M22: ='NeatRescue — Revenue & costs ·'!M16*'NeatRescue — Assumptions & (2)'!B6 -> 3446.7706
A23: Verification overage revenue | B23: =SUM('NeatRescue — Revenue & costs ·'!B24,'NeatRescue — Revenue & costs ·'!B25) -> 24 | C23: =SUM('NeatRescue — Revenue & costs ·'!C24,'NeatRescue — Revenue & costs ·'!C25) -> 49.2 | D23: =SUM('NeatRescue — Revenue & costs ·'!D24,'NeatRescue — Revenue & costs ·'!D25) -> 75.78 | E23: =SUM('NeatRescue — Revenue & costs ·'!E24,'NeatRescue — Revenue & costs ·'!E25) -> 103.935 | F23: =SUM('NeatRescue — Revenue & costs ·'!F24,'NeatRescue — Revenue & costs ·'!F25) -> 133.87665 | G23: =SUM('NeatRescue — Revenue & costs ·'!G24,'NeatRescue — Revenue & costs ·'!G25) -> 165.83506 | H23: =SUM('NeatRescue — Revenue & costs ·'!H24,'NeatRescue — Revenue & costs ·'!H25) -> 200.06077 | I23: =SUM('NeatRescue — Revenue & costs ·'!I24,'NeatRescue — Revenue & costs ·'!I25) -> 236.82694 | ... M23: =SUM('NeatRescue — Revenue & costs ·'!M24,'NeatRescue — Revenue & costs ·'!M25) -> 415.69093
A24: Starter | B24: ='NeatRescue — Revenue & costs ·'!B15*MAX('NeatRescue — Assumptions & (2)'!D5-'NeatRescue — Assumptions & (2)'!C5,0)*'NeatRescue — Assumptions & (2)'!E5 -> 4 | C24: ='NeatRescue — Revenue & costs ·'!C15*MAX('NeatRescue — Assumptions & (2)'!D5-'NeatRescue — Assumptions & (2)'!C5,0)*'NeatRescue — Assumptions & (2)'!E5 -> 8.2 | D24: ='NeatRescue — Revenue & costs ·'!D15*MAX('NeatRescue — Assumptions & (2)'!D5-'NeatRescue — Assumptions & (2)'!C5,0)*'NeatRescue — Assumptions & (2)'!E5 -> 12.63 | E24: ='NeatRescue — Revenue & costs ·'!E15*MAX('NeatRescue — Assumptions & (2)'!D5-'NeatRescue — Assumptions & (2)'!C5,0)*'NeatRescue — Assumptions & (2)'!E5 -> 17.3225 | F24: ='NeatRescue — Revenue & costs ·'!F15*MAX('NeatRescue — Assumptions & (2)'!D5-'NeatRescue — Assumptions & (2)'!C5,0)*'NeatRescue — Assumptions & (2)'!E5 -> 22.312775 | G24: ='NeatRescue — Revenue & costs ·'!G15*MAX('NeatRescue — Assumptions & (2)'!D5-'NeatRescue — Assumptions & (2)'!C5,0)*'NeatRescue — Assumptions & (2)'!E5 -> 27.639176 | H24: ='NeatRescue — Revenue & costs ·'!H15*MAX('NeatRescue — Assumptions & (2)'!D5-'NeatRescue — Assumptions & (2)'!C5,0)*'NeatRescue — Assumptions & (2)'!E5 -> 33.343461 | I24: ='NeatRescue — Revenue & costs ·'!I15*MAX('NeatRescue — Assumptions & (2)'!D5-'NeatRescue — Assumptions & (2)'!C5,0)*'NeatRescue — Assumptions & (2)'!E5 -> 39.471157 | J24: ='NeatRescue — Revenue & costs ·'!J15*MAX('NeatRescue — Assumptions & (2)'!D5-'NeatRescue — Assumptions & (2)'!C5,0)*'NeatRescue — Assumptions & (2)'!E5 -> 46.071954 | K24: ='NeatRescue — Revenue & costs ·'!K15*MAX('NeatRescue — Assumptions & (2)'!D5-'NeatRescue — Assumptions & (2)'!C5,0)*'NeatRescue — Assumptions & (2)'!E5 -> 53.200147 | L24: ='NeatRescue — Revenue & costs ·'!L15*MAX('NeatRescue — Assumptions & (2)'!D5-'NeatRescue — Assumptions & (2)'!C5,0)*'NeatRescue — Assumptions & (2)'!E5 -> 60.91511 | M24: ='NeatRescue — Revenue & costs ·'!M15*MAX('NeatRescue — Assumptions & (2)'!D5-'NeatRescue — Assumptions & (2)'!C5,0)*'NeatRescue — Assumptions & (2)'!E5 -> 69.281821
A25: Team | B25: ='NeatRescue — Revenue & costs ·'!B16*MAX('NeatRescue — Assumptions & (2)'!D6-'NeatRescue — Assumptions & (2)'!C6,0)*'NeatRescue — Assumptions & (2)'!E6 -> 20 | C25: ='NeatRescue — Revenue & costs ·'!C16*MAX('NeatRescue — Assumptions & (2)'!D6-'NeatRescue — Assumptions & (2)'!C6,0)*'NeatRescue — Assumptions & (2)'!E6 -> 41 | D25: ='NeatRescue — Revenue & costs ·'!D16*MAX('NeatRescue — Assumptions & (2)'!D6-'NeatRescue — Assumptions & (2)'!C6,0)*'NeatRescue — Assumptions & (2)'!E6 -> 63.15 | E25: ='NeatRescue — Revenue & costs ·'!E16*MAX('NeatRescue — Assumptions & (2)'!D6-'NeatRescue — Assumptions & (2)'!C6,0)*'NeatRescue — Assumptions & (2)'!E6 -> 86.6125 | F25: ='NeatRescue — Revenue & costs ·'!F16*MAX('NeatRescue — Assumptions & (2)'!D6-'NeatRescue — Assumptions & (2)'!C6,0)*'NeatRescue — Assumptions & (2)'!E6 -> 111.56388 | G25: ='NeatRescue — Revenue & costs ·'!G16*MAX('NeatRescue — Assumptions & (2)'!D6-'NeatRescue — Assumptions & (2)'!C6,0)*'NeatRescue — Assumptions & (2)'!E6 -> 138.19588 | H25: ='NeatRescue — Revenue & costs ·'!H16*MAX('NeatRescue — Assumptions & (2)'!D6-'NeatRescue — Assumptions & (2)'!C6,0)*'NeatRescue — Assumptions & (2)'!E6 -> 166.71731 | I25: ='NeatRescue — Revenue & costs ·'!I16*MAX('NeatRescue — Assumptions & (2)'!D6-'NeatRescue — Assumptions & (2)'!C6,0)*'NeatRescue — Assumptions & (2)'!E6 -> 197.35578 | J25: ='NeatRescue — Revenue & costs ·'!J16*MAX('NeatRescue — Assumptions & (2)'!D6-'NeatRescue — Assumptions & (2)'!C6,0)*'NeatRescue — Assumptions & (2)'!E6 -> 230.35977 | K25: ='NeatRescue — Revenue & costs ·'!K16*MAX('NeatRescue — Assumptions & (2)'!D6-'NeatRescue — Assumptions & (2)'!C6,0)*'NeatRescue — Assumptions & (2)'!E6 -> 266.00074 | L25: ='NeatRescue — Revenue & costs ·'!L16*MAX('NeatRescue — Assumptions & (2)'!D6-'NeatRescue — Assumptions & (2)'!C6,0)*'NeatRescue — Assumptions & (2)'!E6 -> 304.57555 | M25: ='NeatRescue — Revenue & costs ·'!M16*MAX('NeatRescue — Assumptions & (2)'!D6-'NeatRescue — Assumptions & (2)'!C6,0)*'NeatRescue — Assumptions & (2)'!E6 -> 346.40911
A26: Revenue | B26: =SUM('NeatRescue — Revenue & costs ·'!B27,'NeatRescue — Revenue & costs ·'!B28) -> 321 | C26: =SUM('NeatRescue — Revenue & costs ·'!C27,'NeatRescue — Revenue & costs ·'!C28) -> 658.05 | D26: =SUM('NeatRescue — Revenue & costs ·'!D27,'NeatRescue — Revenue & costs ·'!D28) -> 1013.5575 | E26: =SUM('NeatRescue — Revenue & costs ·'!E27,'NeatRescue — Revenue & costs ·'!E28) -> 1390.1306 | F26: =SUM('NeatRescue — Revenue & costs ·'!F27,'NeatRescue — Revenue & costs ·'!F28) -> 1790.6002 | G26: =SUM('NeatRescue — Revenue & costs ·'!G27,'NeatRescue — Revenue & costs ·'!G28) -> 2218.0439 | H26: =SUM('NeatRescue — Revenue & costs ·'!H27,'NeatRescue — Revenue & costs ·'!H28) -> 2675.8128 | I26: =SUM('NeatRescue — Revenue & costs ·'!I27,'NeatRescue — Revenue & costs ·'!I28) -> 3167.5603 | ... M26: =SUM('NeatRescue — Revenue & costs ·'!M27,'NeatRescue — Revenue & costs ·'!M28) -> 5559.8661
A27: Starter | B27: ='NeatRescue — Revenue & costs ·'!B21+'NeatRescue — Revenue & costs ·'!B24 -> 102 | C27: ='NeatRescue — Revenue & costs ·'!C21+'NeatRescue — Revenue & costs ·'!C24 -> 209.1 | D27: ='NeatRescue — Revenue & costs ·'!D21+'NeatRescue — Revenue & costs ·'!D24 -> 322.065 | E27: ='NeatRescue — Revenue & costs ·'!E21+'NeatRescue — Revenue & costs ·'!E24 -> 441.72375 | F27: ='NeatRescue — Revenue & costs ·'!F21+'NeatRescue — Revenue & costs ·'!F24 -> 568.97576 | G27: ='NeatRescue — Revenue & costs ·'!G21+'NeatRescue — Revenue & costs ·'!G24 -> 704.79899 | H27: ='NeatRescue — Revenue & costs ·'!H21+'NeatRescue — Revenue & costs ·'!H24 -> 850.25827 | I27: ='NeatRescue — Revenue & costs ·'!I21+'NeatRescue — Revenue & costs ·'!I24 -> 1006.5145 | ... M27: ='NeatRescue — Revenue & costs ·'!M21+'NeatRescue — Revenue & costs ·'!M24 -> 1766.6864
A28: Team | B28: ='NeatRescue — Revenue & costs ·'!B22+'NeatRescue — Revenue & costs ·'!B25 -> 219 | C28: ='NeatRescue — Revenue & costs ·'!C22+'NeatRescue — Revenue & costs ·'!C25 -> 448.95 | D28: ='NeatRescue — Revenue & costs ·'!D22+'NeatRescue — Revenue & costs ·'!D25 -> 691.4925 | E28: ='NeatRescue — Revenue & costs ·'!E22+'NeatRescue — Revenue & costs ·'!E25 -> 948.40688 | F28: ='NeatRescue — Revenue & costs ·'!F22+'NeatRescue — Revenue & costs ·'!F25 -> 1221.6244 | G28: ='NeatRescue — Revenue & costs ·'!G22+'NeatRescue — Revenue & costs ·'!G25 -> 1513.2449 | H28: ='NeatRescue — Revenue & costs ·'!H22+'NeatRescue — Revenue & costs ·'!H25 -> 1825.5545 | I28: ='NeatRescue — Revenue & costs ·'!I22+'NeatRescue — Revenue & costs ·'!I25 -> 2161.0458 | ... M28: ='NeatRescue — Revenue & costs ·'!M22+'NeatRescue — Revenue & costs ·'!M25 -> 3793.1797
A29: Inference expense | B29: =SUM('NeatRescue — Revenue & costs ·'!B30,'NeatRescue — Revenue & costs ·'!B31) -> 52 | C29: =SUM('NeatRescue — Revenue & costs ·'!C30,'NeatRescue — Revenue & costs ·'!C31) -> 106.6 | D29: =SUM('NeatRescue — Revenue & costs ·'!D30,'NeatRescue — Revenue & costs ·'!D31) -> 164.19 | E29: =SUM('NeatRescue — Revenue & costs ·'!E30,'NeatRescue — Revenue & costs ·'!E31) -> 225.1925 | F29: =SUM('NeatRescue — Revenue & costs ·'!F30,'NeatRescue — Revenue & costs ·'!F31) -> 290.06608 | G29: =SUM('NeatRescue — Revenue & costs ·'!G30,'NeatRescue — Revenue & costs ·'!G31) -> 359.30929 | H29: =SUM('NeatRescue — Revenue & costs ·'!H30,'NeatRescue — Revenue & costs ·'!H31) -> 433.465 | I29: =SUM('NeatRescue — Revenue & costs ·'!I30,'NeatRescue — Revenue & costs ·'!I31) -> 513.12504 | ... M29: =SUM('NeatRescue — Revenue & costs ·'!M30,'NeatRescue — Revenue & costs ·'!M31) -> 900.66367
A30: Starter | B30: ='NeatRescue — Revenue & costs ·'!B18*'NeatRescue — Assumptions & simu'!B7 -> 12 | C30: ='NeatRescue — Revenue & costs ·'!C18*'NeatRescue — Assumptions & simu'!B7 -> 24.6 | D30: ='NeatRescue — Revenue & costs ·'!D18*'NeatRescue — Assumptions & simu'!B7 -> 37.89 | E30: ='NeatRescue — Revenue & costs ·'!E18*'NeatRescue — Assumptions & simu'!B7 -> 51.9675 | F30: ='NeatRescue — Revenue & costs ·'!F18*'NeatRescue — Assumptions & simu'!B7 -> 66.938325 | G30: ='NeatRescue — Revenue & costs ·'!G18*'NeatRescue — Assumptions & simu'!B7 -> 82.917529 | H30: ='NeatRescue — Revenue & costs ·'!H18*'NeatRescue — Assumptions & simu'!B7 -> 100.03038 | I30: ='NeatRescue — Revenue & costs ·'!I18*'NeatRescue — Assumptions & simu'!B7 -> 118.41347 | J30: ='NeatRescue — Revenue & costs ·'!J18*'NeatRescue — Assumptions & simu'!B7 -> 138.21586 | K30: ='NeatRescue — Revenue & costs ·'!K18*'NeatRescue — Assumptions & simu'!B7 -> 159.60044 | L30: ='NeatRescue — Revenue & costs ·'!L18*'NeatRescue — Assumptions & simu'!B7 -> 182.74533 | M30: ='NeatRescue — Revenue & costs ·'!M18*'NeatRescue — Assumptions & simu'!B7 -> 207.84546
A31: Team | B31: ='NeatRescue — Revenue & costs ·'!B19*'NeatRescue — Assumptions & simu'!B7 -> 40 | C31: ='NeatRescue — Revenue & costs ·'!C19*'NeatRescue — Assumptions & simu'!B7 -> 82 | D31: ='NeatRescue — Revenue & costs ·'!D19*'NeatRescue — Assumptions & simu'!B7 -> 126.3 | E31: ='NeatRescue — Revenue & costs ·'!E19*'NeatRescue — Assumptions & simu'!B7 -> 173.225 | F31: ='NeatRescue — Revenue & costs ·'!F19*'NeatRescue — Assumptions & simu'!B7 -> 223.12775 | G31: ='NeatRescue — Revenue & costs ·'!G19*'NeatRescue — Assumptions & simu'!B7 -> 276.39176 | H31: ='NeatRescue — Revenue & costs ·'!H19*'NeatRescue — Assumptions & simu'!B7 -> 333.43461 | I31: ='NeatRescue — Revenue & costs ·'!I19*'NeatRescue — Assumptions & simu'!B7 -> 394.71157 | J31: ='NeatRescue — Revenue & costs ·'!J19*'NeatRescue — Assumptions & simu'!B7 -> 460.71954 | K31: ='NeatRescue — Revenue & costs ·'!K19*'NeatRescue — Assumptions & simu'!B7 -> 532.00147 | L31: ='NeatRescue — Revenue & costs ·'!L19*'NeatRescue — Assumptions & simu'!B7 -> 609.1511 | M31: ='NeatRescue — Revenue & costs ·'!M19*'NeatRescue — Assumptions & simu'!B7 -> 692.81821
A32: Variable compute expense | B32: =SUM('NeatRescue — Revenue & costs ·'!B33,'NeatRescue — Revenue & costs ·'!B34) -> 15.6 | C32: =SUM('NeatRescue — Revenue & costs ·'!C33,'NeatRescue — Revenue & costs ·'!C34) -> 31.98 | D32: =SUM('NeatRescue — Revenue & costs ·'!D33,'NeatRescue — Revenue & costs ·'!D34) -> 49.257 | E32: =SUM('NeatRescue — Revenue & costs ·'!E33,'NeatRescue — Revenue & costs ·'!E34) -> 67.55775 | F32: =SUM('NeatRescue — Revenue & costs ·'!F33,'NeatRescue — Revenue & costs ·'!F34) -> 87.019823 | G32: =SUM('NeatRescue — Revenue & costs ·'!G33,'NeatRescue — Revenue & costs ·'!G34) -> 107.79279 | H32: =SUM('NeatRescue — Revenue & costs ·'!H33,'NeatRescue — Revenue & costs ·'!H34) -> 130.0395 | I32: =SUM('NeatRescue — Revenue & costs ·'!I33,'NeatRescue — Revenue & costs ·'!I34) -> 153.93751 | ... M32: =SUM('NeatRescue — Revenue & costs ·'!M33,'NeatRescue — Revenue & costs ·'!M34) -> 270.1991
A33: Starter | B33: ='NeatRescue — Revenue & costs ·'!B18*'NeatRescue — Assumptions & simu'!B8 -> 3.6 | C33: ='NeatRescue — Revenue & costs ·'!C18*'NeatRescue — Assumptions & simu'!B8 -> 7.38 | D33: ='NeatRescue — Revenue & costs ·'!D18*'NeatRescue — Assumptions & simu'!B8 -> 11.367 | E33: ='NeatRescue — Revenue & costs ·'!E18*'NeatRescue — Assumptions & simu'!B8 -> 15.59025 | F33: ='NeatRescue — Revenue & costs ·'!F18*'NeatRescue — Assumptions & simu'!B8 -> 20.081498 | G33: ='NeatRescue — Revenue & costs ·'!G18*'NeatRescue — Assumptions & simu'!B8 -> 24.875259 | H33: ='NeatRescue — Revenue & costs ·'!H18*'NeatRescue — Assumptions & simu'!B8 -> 30.009115 | I33: ='NeatRescue — Revenue & costs ·'!I18*'NeatRescue — Assumptions & simu'!B8 -> 35.524041 | J33: ='NeatRescue — Revenue & costs ·'!J18*'NeatRescue — Assumptions & simu'!B8 -> 41.464759 | K33: ='NeatRescue — Revenue & costs ·'!K18*'NeatRescue — Assumptions & simu'!B8 -> 47.880133 | L33: ='NeatRescue — Revenue & costs ·'!L18*'NeatRescue — Assumptions & simu'!B8 -> 54.823599 | M33: ='NeatRescue — Revenue & costs ·'!M18*'NeatRescue — Assumptions & simu'!B8 -> 62.353639
A34: Team | B34: ='NeatRescue — Revenue & costs ·'!B19*'NeatRescue — Assumptions & simu'!B8 -> 12 | C34: ='NeatRescue — Revenue & costs ·'!C19*'NeatRescue — Assumptions & simu'!B8 -> 24.6 | D34: ='NeatRescue — Revenue & costs ·'!D19*'NeatRescue — Assumptions & simu'!B8 -> 37.89 | E34: ='NeatRescue — Revenue & costs ·'!E19*'NeatRescue — Assumptions & simu'!B8 -> 51.9675 | F34: ='NeatRescue — Revenue & costs ·'!F19*'NeatRescue — Assumptions & simu'!B8 -> 66.938325 | G34: ='NeatRescue — Revenue & costs ·'!G19*'NeatRescue — Assumptions & simu'!B8 -> 82.917529 | H34: ='NeatRescue — Revenue & costs ·'!H19*'NeatRescue — Assumptions & simu'!B8 -> 100.03038 | I34: ='NeatRescue — Revenue & costs ·'!I19*'NeatRescue — Assumptions & simu'!B8 -> 118.41347 | J34: ='NeatRescue — Revenue & costs ·'!J19*'NeatRescue — Assumptions & simu'!B8 -> 138.21586 | K34: ='NeatRescue — Revenue & costs ·'!K19*'NeatRescue — Assumptions & simu'!B8 -> 159.60044 | L34: ='NeatRescue — Revenue & costs ·'!L19*'NeatRescue — Assumptions & simu'!B8 -> 182.74533 | M34: ='NeatRescue — Revenue & costs ·'!M19*'NeatRescue — Assumptions & simu'!B8 -> 207.84546
A35: Variable logging expense | B35: =SUM('NeatRescue — Revenue & costs ·'!B36,'NeatRescue — Revenue & costs ·'!B37) -> 5.2 | C35: =SUM('NeatRescue — Revenue & costs ·'!C36,'NeatRescue — Revenue & costs ·'!C37) -> 10.66 | D35: =SUM('NeatRescue — Revenue & costs ·'!D36,'NeatRescue — Revenue & costs ·'!D37) -> 16.419 | E35: =SUM('NeatRescue — Revenue & costs ·'!E36,'NeatRescue — Revenue & costs ·'!E37) -> 22.51925 | F35: =SUM('NeatRescue — Revenue & costs ·'!F36,'NeatRescue — Revenue & costs ·'!F37) -> 29.006608 | G35: =SUM('NeatRescue — Revenue & costs ·'!G36,'NeatRescue — Revenue & costs ·'!G37) -> 35.930929 | H35: =SUM('NeatRescue — Revenue & costs ·'!H36,'NeatRescue — Revenue & costs ·'!H37) -> 43.3465 | I35: =SUM('NeatRescue — Revenue & costs ·'!I36,'NeatRescue — Revenue & costs ·'!I37) -> 51.312504 | ... M35: =SUM('NeatRescue — Revenue & costs ·'!M36,'NeatRescue — Revenue & costs ·'!M37) -> 90.066367
A36: Starter | B36: ='NeatRescue — Revenue & costs ·'!B18*'NeatRescue — Assumptions & simu'!B9 -> 1.2 | C36: ='NeatRescue — Revenue & costs ·'!C18*'NeatRescue — Assumptions & simu'!B9 -> 2.46 | D36: ='NeatRescue — Revenue & costs ·'!D18*'NeatRescue — Assumptions & simu'!B9 -> 3.789 | E36: ='NeatRescue — Revenue & costs ·'!E18*'NeatRescue — Assumptions & simu'!B9 -> 5.19675 | F36: ='NeatRescue — Revenue & costs ·'!F18*'NeatRescue — Assumptions & simu'!B9 -> 6.6938325 | G36: ='NeatRescue — Revenue & costs ·'!G18*'NeatRescue — Assumptions & simu'!B9 -> 8.2917529 | H36: ='NeatRescue — Revenue & costs ·'!H18*'NeatRescue — Assumptions & simu'!B9 -> 10.003038 | I36: ='NeatRescue — Revenue & costs ·'!I18*'NeatRescue — Assumptions & simu'!B9 -> 11.841347 | J36: ='NeatRescue — Revenue & costs ·'!J18*'NeatRescue — Assumptions & simu'!B9 -> 13.821586 | K36: ='NeatRescue — Revenue & costs ·'!K18*'NeatRescue — Assumptions & simu'!B9 -> 15.960044 | L36: ='NeatRescue — Revenue & costs ·'!L18*'NeatRescue — Assumptions & simu'!B9 -> 18.274533 | M36: ='NeatRescue — Revenue & costs ·'!M18*'NeatRescue — Assumptions & simu'!B9 -> 20.784546
A37: Team | B37: ='NeatRescue — Revenue & costs ·'!B19*'NeatRescue — Assumptions & simu'!B9 -> 4 | C37: ='NeatRescue — Revenue & costs ·'!C19*'NeatRescue — Assumptions & simu'!B9 -> 8.2 | D37: ='NeatRescue — Revenue & costs ·'!D19*'NeatRescue — Assumptions & simu'!B9 -> 12.63 | E37: ='NeatRescue — Revenue & costs ·'!E19*'NeatRescue — Assumptions & simu'!B9 -> 17.3225 | F37: ='NeatRescue — Revenue & costs ·'!F19*'NeatRescue — Assumptions & simu'!B9 -> 22.312775 | G37: ='NeatRescue — Revenue & costs ·'!G19*'NeatRescue — Assumptions & simu'!B9 -> 27.639176 | H37: ='NeatRescue — Revenue & costs ·'!H19*'NeatRescue — Assumptions & simu'!B9 -> 33.343461 | I37: ='NeatRescue — Revenue & costs ·'!I19*'NeatRescue — Assumptions & simu'!B9 -> 39.471157 | J37: ='NeatRescue — Revenue & costs ·'!J19*'NeatRescue — Assumptions & simu'!B9 -> 46.071954 | K37: ='NeatRescue — Revenue & costs ·'!K19*'NeatRescue — Assumptions & simu'!B9 -> 53.200147 | L37: ='NeatRescue — Revenue & costs ·'!L19*'NeatRescue — Assumptions & simu'!B9 -> 60.91511 | M37: ='NeatRescue — Revenue & costs ·'!M19*'NeatRescue — Assumptions & simu'!B9 -> 69.281821
A38: Variable support expense | B38: =SUM('NeatRescue — Revenue & costs ·'!B39,'NeatRescue — Revenue & costs ·'!B40) -> 16 | C38: =SUM('NeatRescue — Revenue & costs ·'!C39,'NeatRescue — Revenue & costs ·'!C40) -> 32.8 | D38: =SUM('NeatRescue — Revenue & costs ·'!D39,'NeatRescue — Revenue & costs ·'!D40) -> 50.52 | E38: =SUM('NeatRescue — Revenue & costs ·'!E39,'NeatRescue — Revenue & costs ·'!E40) -> 69.29 | F38: =SUM('NeatRescue — Revenue & costs ·'!F39,'NeatRescue — Revenue & costs ·'!F40) -> 89.2511 | G38: =SUM('NeatRescue — Revenue & costs ·'!G39,'NeatRescue — Revenue & costs ·'!G40) -> 110.55671 | H38: =SUM('NeatRescue — Revenue & costs ·'!H39,'NeatRescue — Revenue & costs ·'!H40) -> 133.37385 | I38: =SUM('NeatRescue — Revenue & costs ·'!I39,'NeatRescue — Revenue & costs ·'!I40) -> 157.88463 | ... M38: =SUM('NeatRescue — Revenue & costs ·'!M39,'NeatRescue — Revenue & costs ·'!M40) -> 277.12728
